<?xml version="1.0" encoding="utf-8"?>
<robot xmlns:xacro="http://www.ros.org/wiki/xacro" name="arabian_robot" >

<xacro:include filename="$(find arabian_robot)/urdf/arabian_robot_sensors.xacro" />
<xacro:include filename="$(find arabian_robot)/urdf/plugin_diff.gazebo" />    
<xacro:include filename="$(find arabian_robot)/urdf/plugin_sensors.gazebo" />  

<link name="base_footprint"> 

</link>

<joint name="base_footprint_joint" type="fixed">
      <origin
        xyz="0.0 0.0 0"
        rpy="0 0 0" />
    <parent link ="base_footprint"/>
    <child link ="base_link"/>   
</joint>


  <link
    name="base_link">
    <inertial>
      <origin
        xyz="-0.00133744334022522 6.05357174165988E-07 -0.00970131886296771"
        rpy="0 0 0" />
      <mass
        value="1.1439176852714" />
      <inertia
        ixx="0.446134400302526"
        ixy="-2.18000480348373E-05"
        ixz="0.0113470100455749"
        iyy="0.985173237691484"
        iyz="2.52721045797753E-06"
        izz="1.332699788346" />
    </inertial>
    <visual>
      <origin
        xyz="0 0 0"
        rpy="0 0 0" />
      <geometry>
        <mesh
          filename="package://arabian_robot/meshes/base_link.STL" />
      </geometry>
      <material
        name="LightBlue">
        <color
          rgba="0.792156862745098 0.819607843137255 0.933333333333333 1" />
      </material>
    </visual>
    <collision>
      <origin
        xyz="0 0 0"
        rpy="0 0 0" />
      <geometry>
        <mesh
          filename="package://arabian_robot/meshes/base_link.STL" />
      </geometry>
    </collision>
  </link>
 
   <link
    name="front_right_wheel">
    <inertial>
      <origin
        xyz="-5.92307982660856E-07 0.00883833779366749 -4.20445877558073E-08"
        rpy="0 0 0" />
      <mass
        value="0.260404298470105" />
      <inertia
        ixx="0.000768916188073183"
        ixy="-3.91608887242284E-09"
        ixz="-1.86122419709981E-08"
        iyy="0.00137090251737553"
        iyz="-4.72596045124545E-10"
        izz="0.000769014346730516" />
    </inertial>
    <visual>
      <origin
        xyz="0 0 0"
        rpy="0 0 0" />
      <geometry>
        <mesh
          filename="package://arabian_robot/meshes/front_right_wheel.STL" />
      </geometry>
      <material
        name="blue">
        <color
          rgba="0.2 0.4 0.698039215686274 1" />
      </material>
    </visual>
    <collision>
      <origin
        xyz="0 0 0"
        rpy="0 0 0" />
      <geometry>
        <mesh
          filename="package://arabian_robot/meshes/front_right_wheel.STL" />
      </geometry>
    </collision>
  </link>
  <joint
    name="front_right_wheel_joint"
    type="continuous">
    <origin
      xyz="0.18279 -0.243 -0.014153"
      rpy="0 0 0" />
    <parent
      link="base_link" />
    <child
      link="front_right_wheel" />
    <axis
      xyz="0 1 0" />
  </joint>
  <link
    name="rear_right_wheel">
    <inertial>
      <origin
        xyz="5.91746743994204E-07 0.00865068531718727 4.89179091955894E-08"
        rpy="0 0 0" />
      <mass
        value="0.260404298477464" />
      <inertia
        ixx="0.000768916632775559"
        ixy="3.91036360372682E-09"
        ixz="-1.97450781846868E-08"
        iyy="0.00137090251739636"
        iyz="5.1794015532165E-10"
        izz="0.000769013902049739" />
    </inertial>
    <visual>
      <origin
        xyz="0 0 0"
        rpy="0 0 0" />
      <geometry>
        <mesh
          filename="package://arabian_robot/meshes/rear_right_wheel.STL" />
      </geometry>
      <material
        name="blue">
        <color
          rgba="0.2 0.4 0.698039215686274 1" />
      </material>
    </visual>
    <collision>
      <origin
        xyz="0 0 0"
        rpy="0 0 0" />
      <geometry>
        <mesh
          filename="package://arabian_robot/meshes/rear_right_wheel.STL" />
      </geometry>
    </collision>
  </link>
  <joint
    name="rear_right_wheel_joint"
    type="continuous">
    <origin
      xyz="-0.17721 -0.24281 -0.014153"
      rpy="0 0 0" />
    <parent
      link="base_link" />
    <child
      link="rear_right_wheel" />
    <axis
      xyz="0 1 0" />
  </joint>
  <link
    name="front_left_wheel">
    <inertial>
      <origin
        xyz="-5.43240281369872E-07 -0.0088383378086567 2.3961098227776E-07"
        rpy="0 0 0" />
      <mass
        value="0.260404298193649" />
      <inertia
        ixx="0.000768939223288773"
        ixy="3.52640785354548E-09"
        ixz="4.55730439449201E-08"
        iyy="0.00137090251681853"
        iyz="-1.76774536234723E-09"
        izz="0.000768991310917154" />
    </inertial>
    <visual>
      <origin
        xyz="0 0 0"
        rpy="0 0 0" />
      <geometry>
        <mesh
          filename="package://arabian_robot/meshes/front_left_wheel.STL" />
      </geometry>
      <material
        name="blue">
        <color
          rgba="0.2 0.4 0.698039215686274 1" />
      </material>
    </visual>
    <collision>
      <origin
        xyz="0 0 0"
        rpy="0 0 0" />
      <geometry>
        <mesh
          filename="package://arabian_robot/meshes/front_left_wheel.STL" />
      </geometry>
    </collision>
  </link>
  <joint
    name="front_left_wheel_joint"
    type="continuous">
    <origin
      xyz="0.18279 0.243 -0.014153"
      rpy="0 0 0" />
    <parent
      link="base_link" />
    <child
      link="front_left_wheel" />
    <axis
      xyz="0 1 0" />
  </joint>
  <link
    name="rear_left_wheel">
    <inertial>
      <origin
        xyz="-5.77441466698136E-07 -0.0088383378011283 1.38298648810764E-07"
        rpy="0 0 0" />
      <mass
        value="0.260404298330934" />
      <inertia
        ixx="0.000768924810397154"
        ixy="3.78629360408607E-09"
        ixz="3.34428239014459E-08"
        iyy="0.00137090251712043"
        iyz="-1.10616458599264E-09"
        izz="0.000769005724131009" />
    </inertial>
    <visual>
      <origin
        xyz="0 0 0"
        rpy="0 0 0" />
      <geometry>
        <mesh
          filename="package://arabian_robot/meshes/rear_left_wheel.STL" />
      </geometry>
      <material
        name="blue">
        <color
          rgba="0.2 0.4 0.698039215686274 1" />
      </material>
    </visual>
    <collision>
      <origin
        xyz="0 0 0"
        rpy="0 0 0" />
      <geometry>
        <mesh
          filename="package://arabian_robot/meshes/rear_left_wheel.STL" />
      </geometry>
    </collision>
  </link>
  <joint
    name="rear_left_wheel_joint"
    type="continuous">
    <origin
      xyz="-0.17721 0.243 -0.014153"
      rpy="0 0 0" />
    <parent
      link="base_link" />
    <child
      link="rear_left_wheel" />
    <axis
      xyz="0 1 0" />
  </joint> 
  

<gazebo reference="base_link">
  <material>Gazebo/White</material>  
</gazebo>

<gazebo reference="front_left_wheel">
  <material>Gazebo/Black</material> 
</gazebo>
<gazebo reference="front_right_wheel">
  <material>Gazebo/Black</material>  
</gazebo>
<gazebo reference="rear_left_wheel">
  <material>Gazebo/Black</material>  
</gazebo>
<gazebo reference="rear_right_wheel">
  <material>Gazebo/Black</material>  
</gazebo>
  
 





</robot>
